#VRML_SIM R2022b utf8
# license: Apache License 2.0
# license url: http://www.apache.org/licenses/LICENSE-2.0
# This is a proto file for Webots for the Servoarm

PROTO Servoarm [
  field  SFVec3f     translation     0 0 0
  field  SFRotation  rotation        0 0 1 0
  field  SFString    name            "Servoarm"  # Is `Robot.name`.
  field  SFString    controller      "void"      # Is `Robot.controller`.
  field  MFString    controllerArgs  []          # Is `Robot.controllerArgs`.
  field  SFString    customData      ""          # Is `Robot.customData`.
  field  SFBool      supervisor      TRUE        # Is `Robot.supervisor`.
  field  SFBool      synchronization TRUE        # Is `Robot.synchronization`.
  field  SFBool      selfCollision   FALSE       # Is `Robot.selfCollision`.
]
{
  Robot {
    translation IS translation
    rotation IS rotation
    controller IS controller
    controllerArgs IS controllerArgs
    customData IS customData
    supervisor IS supervisor
    synchronization IS synchronization
    selfCollision IS selfCollision
    children [
      CadShape {
        url [
          "meshes/base.obj"
        ]
      }
      HingeJoint {
        jointParameters HingeJointParameters {
          axis 0 0 1
          anchor 0 0 0.068
        }
        device [
          RotationalMotor {
            name "joint1"
            minPosition -3.1415
            maxPosition 3.1415
          }
          PositionSensor {
            name "sensor1"
          }
        ]
        endPoint Solid {
          translation 0 0 0.068
          rotation 0 0 1 1.5708
          children [
            CadShape {
              url [
                "meshes/plate.obj"
              ]
            }
            HingeJoint {
              jointParameters HingeJointParameters {
                axis 0 -1 0
                anchor 0.0192 0 0
              }
              device [
                RotationalMotor {
                  name "joint2"
                  maxPosition 3.14
                }
                PositionSensor {
                  name "sensor2"
                }
              ]
              endPoint Solid {
                translation 0.0192 0 0
                rotation 1 0 0 1.5708
                children [
                  CadShape {
                    url [
                      "meshes/lower-arm.obj"
                    ]
                  }
                  HingeJoint {
                    jointParameters HingeJointParameters {
                      axis 0 0 1
                      anchor 0.1028 0 0
                    }
                    device [
                      RotationalMotor {
                        name "joint3"
                        minPosition -3.1415
                        maxPosition 3.1415
                      }
                      PositionSensor {
                        name "sensor3"
                      }
                    ]
                    endPoint Solid {
                      translation 0.1028 0 0
                      children [
                        CadShape {
                          url [
                            "meshes/top-arm.obj"
                          ]
                        }
                        HingeJoint {
                          jointParameters HingeJointParameters {
                            axis 0 0 1
                            anchor 0.0747 0 0
                          }
                          device [
                            RotationalMotor {
                              name "joint4"
                              minPosition -3.1415
                              maxPosition 3.1415
                            }
                            PositionSensor {
                              name "sensor4"
                            }
                          ]
                          endPoint Solid {
                            translation 0.0747 0 0
                            children [
                              CadShape {
                                url [
                                  "meshes/wrist.obj"
                                ]
                              }
                              HingeJoint {
                                jointParameters HingeJointParameters {
                                  anchor 0.0688 0 -0.0116
                                }
                                device [
                                  RotationalMotor {
                                    name "joint5"
                                    minPosition -3.1415
                                    maxPosition 3.1415
                                  }
                                  PositionSensor {
                                    name "sensor5"
                                  }
                                ]
                                endPoint Solid {
                                  translation 0.0688 0 -0.0116
                                  rotation 0.5773502691896258 0.5773502691896258 0.5773502691896258 2.0944
                                  children [
                                    CadShape {
                                      url [
                                        "meshes/claw.obj"
                                      ]
                                    }
                                  ]
                                  boundingObject Transform {
                                    translation 0 0 0.02
                                    children [
                                      Box {
                                        size 0.04 0.05 0.05
                                      }
                                    ]
                                  }
                                  physics Physics {
                                  }
                                }
                              }
                            ]
                            boundingObject Transform {
                              translation 0.016 0 0
                              children [
                                Box {
                                  size 0.092 0.029 0.057
                                }
                              ]
                            }
                            physics Physics {
                            }
                          }
                        }
                      ]
                      boundingObject Transform {
                        translation 0.025 0 0
                        children [
                          Box {
                            size 0.122 0.029 0.057
                          }
                        ]
                      }
                      physics Physics {
                      }
                    }
                  }
                ]
                boundingObject Transform {
                  translation 0.052 0 0
                  children [
                    Box {
                      size 0.122 0.029 0.057
                    }
                  ]
                }
                physics Physics {
                }
              }
            }
          ]
          boundingObject Box {
            size 0.06 0.05 0.03
          }
          physics Physics {
          }
        }
      }
    ]
    name IS name
    boundingObject Transform {
      translation 0 0 0.023
      children [
        Cylinder {
          height 0.05
          radius 0.056
        }
      ]
    }
    controller IS controller
  }
}
